<?xml version="1.0" encoding="UTF-8"?>
<!-- Generated by org.testng.reporters.JUnitReportReporter -->
<testsuite skipped="0" hostname="DESKTOP-DO54GIB" name="swarnajit.DataProviderpractice$ExceptionTestDemo" tests="2" failures="0" timestamp="13 Jan 2019 12:28:39 GMT" time="0.016" errors="1">
  <testcase name="exceptionTestOne" time="0.012" classname="swarnajit.DataProviderpractice$ExceptionTestDemo"/>
  <testcase name="exceptionTestTwo" time="0.004" classname="swarnajit.DataProviderpractice$ExceptionTestDemo">
    <error type="org.testng.TestException" message="
Expected exception of any of types [class java.io.IOException, class java.lang.NullPointerException] but got java.lang.ArithmeticException">
      <![CDATA[org.testng.TestException: Expected exception of any of types [class java.io.IOException, class java.lang.NullPointerException] but got java.lang.ArithmeticExceptionat org.testng.internal.ExpectedExceptionsHolder.wrongException(ExpectedExceptionsHolder.java:68)at org.testng.internal.Invoker.considerExceptions(Invoker.java:1120)at org.testng.internal.Invoker.invokeMethod(Invoker.java:603)at org.testng.internal.Invoker.invokeTestMethod(Invoker.java:707)at org.testng.internal.Invoker.invokeTestMethods(Invoker.java:979)at org.testng.internal.TestMethodWorker.invokeTestMethods(TestMethodWorker.java:125)at org.testng.internal.TestMethodWorker.run(TestMethodWorker.java:109)at org.testng.TestRunner.privateRun(TestRunner.java:648)at org.testng.TestRunner.run(TestRunner.java:505)at org.testng.SuiteRunner.runTest(SuiteRunner.java:455)at org.testng.SuiteRunner.runSequentially(SuiteRunner.java:450)at org.testng.SuiteRunner.privateRun(SuiteRunner.java:415)at org.testng.SuiteRunner.run(SuiteRunner.java:364)at org.testng.SuiteRunnerWorker.runSuite(SuiteRunnerWorker.java:52)at org.testng.SuiteRunnerWorker.run(SuiteRunnerWorker.java:84)at org.testng.TestNG.runSuitesSequentially(TestNG.java:1187)at org.testng.TestNG.runSuitesLocally(TestNG.java:1116)at org.testng.TestNG.runSuites(TestNG.java:1028)at org.testng.TestNG.run(TestNG.java:996)at org.testng.remote.AbstractRemoteTestNG.run(AbstractRemoteTestNG.java:114)at org.testng.remote.RemoteTestNG.initAndRun(RemoteTestNG.java:251)at org.testng.remote.RemoteTestNG.main(RemoteTestNG.java:77)Caused by: java.lang.ArithmeticExceptionat swarnajit.DataProviderpractice$ExceptionTestDemo.exceptionTestTwo(DataProviderpractice.java:57)at sun.reflect.NativeMethodAccessorImpl.invoke0(Native Method)at sun.reflect.NativeMethodAccessorImpl.invoke(NativeMethodAccessorImpl.java:62)at sun.reflect.DelegatingMethodAccessorImpl.invoke(DelegatingMethodAccessorImpl.java:43)at java.lang.reflect.Method.invoke(Method.java:498)at org.testng.internal.MethodInvocationHelper.invokeMethod(MethodInvocationHelper.java:124)at org.testng.internal.Invoker.invokeMethod(Invoker.java:571)... 19 more]]>
    </error>
  </testcase> <!-- exceptionTestTwo -->
</testsuite> <!-- swarnajit.DataProviderpractice$ExceptionTestDemo -->
